Workbook
Name ___xlnm.Print_Titles: Audit!$1:$1
Name __xlnm.Print_Titles: Audit!$A$1:$AB$1
Name Tableau1: Audit!$A$1:$D$440
Name Tableau2: Audit!$A$1:$L$440
Name Tableau3: Config!$A$10:$B$15
Name Tableau4: Config!$D$10:$D$11
Name Tableau5: 'Fiche Audit AOCR 26022018'!$A$1:$T$1401

Sheet Audit
A1: id | B1: Domaine | C1: Sous-domaine | D1: Obligation | E1: Libellé détaillé | F1: Référence | G1: Obligatoire | H1: Avis | I1: Possible réalisateur | J1: Personne obligée | K1: Localisation | L1: Commentaire | M1: Habitation | N1: Travail | O1: ERP/IGH | P1: Modification | Q1: ID Domaine | R1: ID Domaine2 | S1: Colonne1 | T1: Urgence | U1: Validité | V1: Affectation | W1: Hors Contrat | Y1: Dom | Z1: Sdom | AA1: Insert | AB1: Update | AC1: Update Réglementation
A2: 3701 | B2: Accessoire de levage | C2: Carnet de maintenance | D2: Carnet de maintenance de l''accessoire de levage tenu à disposition de l''inspecteur du travail et des organismes des représentants du personnel. | F2: Arrêté du 01/03/2004 Arrêté du 02/03/2004 CDT Art R4323-19 à 4323-21 | H2: Satisfaisant | I2: Personne qualifiée | M2: 1 | N2: 1 | O2: 1 | P2: 0 | Q2: =#REF! -> #REF! | R2: =#REF! -> #REF! | T2: 4 | V2: Propriétaire | Y2: =VLOOKUP(A6,Feuil1!A:B,2,FALSE) -> 421 | Z2: =VLOOKUP(A6,Feuil1!A:C,3,FALSE) -> 524 | AA2: =CONCATENATE("insert into AOCR_ref_arbo (libelle,reglementation,typologie,pere,commentaires,personne_habilitee,type_cont,pere_superieur,criticite) values ('",Tableau6[[#This Row],[Obligation]],"','",Tableau6[[#This Row],[Référence]],"',1,",Tableau6[[#This Row],[ID Domaine2]],",'",Tableau6[[#This Row],[Libellé détaillé]],"','",Tableau6[[#This Row],[Possible réalisateur]],"',3,",Tableau6[[#This Row],[ID Domaine]],",",Tableau6[[#This Row],[Urgence]],")") -> #REF! | AB2: =CONCATENATE("update aocr_ref_arbo set libelle = '",Tableau6[[#This Row],[Obligation]],"', reglementation = '",Tableau6[[#This Row],[Référence]],"', commentaires = '",Tableau6[[#This Row],[Libellé détaillé]],"', personne_habilitee = '",Tableau6[[#This Row],[Possible réalisateur]],"', criticite = ",Tableau6[[#This Row],[Urgence]]," where id = ",Tableau6[[#This Row],[id]]) -> update aocr_ref_arbo set libelle = 'Carnet de maintenance de l''accessoire de levage tenu à disposition de l''inspecteur du travail et des organismes des représentants du personnel.', reglementation = 'Arrêté du 01/03/2004 Arrêté du 02/03/2004 CDT Art R4323-19 à 4323-21', commentaires = '', personne_habilitee = 'Personne qualifiée', criticite = 4 where id = 3701 | AC2: =IF(Tableau6[[#This Row],[Référence]]<>"",CONCATENATE("update aocr_ref_arbo set reglementation = '",Tableau6[[#This Row],[Référence]],"' where id = ",Tableau6[[#This Row],[id]]),"") -> update aocr_ref_arbo set reglementation = 'Arrêté du 01/03/2004 Arrêté du 02/03/2004 CDT Art R4323-19 à 4323-21' where id = 3701
A3: 1906 | B3: Accessoire de levage | C3: Certificat CE | D3: Accessoire de levage CE : Certificat CE pour les équipements postérieurs au 1er Janvier 1993. | F3: Décret n° 93-40 du 11 janvier 1993 relatif aux prescriptions techniques applicables à l''utilisation des équipements de travail soumis à l''article L 233-5-1 du code du travail, aux règles techniques applicables aux matériels d''occasion soumis à l''article L 233-5 du même code et à la mise en conformité des équipements existants et modifiant le code du travail (deuxième partie : Décrets en Conseil d''Etat).; Arrêté du 1er mars 2004 relatif aux vérifications des appareils et accessoires de levage Article 3 | H3: Sans Objet | I3: Fabricant | M3: 1 | N3: 1 | O3: 1 | P3: 0 | Q3: =#REF! -> #REF! | R3: =#REF! -> #REF! | S3: 1 | T3: 5 | V3: Propriétaire | Y3: =VLOOKUP(A7,Feuil1!A:B,2,FALSE) -> 421 | Z3: =VLOOKUP(A7,Feuil1!A:C,3,FALSE) -> 524 | AA3: =CONCATENATE("insert into AOCR_ref_arbo (libelle,reglementation,typologie,pere,commentaires,personne_habilitee,type_cont,pere_superieur,criticite) values ('",Tableau6[[#This Row],[Obligation]],"','",Tableau6[[#This Row],[Référence]],"',1,",Tableau6[[#This Row],[ID Domaine2]],",'",Tableau6[[#This Row],[Libellé détaillé]],"','",Tableau6[[#This Row],[Possible réalisateur]],"',3,",Tableau6[[#This Row],[ID Domaine]],",",Tableau6[[#This Row],[Urgence]],")") -> #REF! | AB3: =CONCATENATE("update aocr_ref_arbo set libelle = '",Tableau6[[#This Row],[Obligation]],"', reglementation = '",Tableau6[[#This Row],[Référence]],"', commentaires = '",Tableau6[[#This Row],[Libellé détaillé]],"', personne_habilitee = '",Tableau6[[#This Row],[Possible réalisateur]],"', criticite = ",Tableau6[[#This Row],[Urgence]]," where id = ",Tableau6[[#This Row],[id]]) -> update aocr_ref_arbo set libelle = 'Accessoire de levage CE : Certificat CE pour les équipements postérieurs au 1er Janvier 1993.', reglementation = 'Décret n° 93-40 du 11 janvier 1993 relatif aux prescriptions techniques applicables à l''utilisation des équipements de travail soumis à l''article L 233-5-1 du code du travail, aux règles techniques applicables aux matériels d''occasion soumis à l''article L 233-5 du même code et à la mise en conformité des équipements existants et modifiant le code du travail (deuxième partie : Décrets en Conseil d''Etat).; Arrêté du 1er mars 2004 relatif aux vérifications des appareils et accessoires de levage Article 3', commentaires = '', personne_habilitee = 'Fabricant', criticite = 5 where id = 1906 | AC3: =IF(Tableau6[[#This Row],[Référence]]<>"",CONCATENATE("update aocr_ref_arbo set reglementation = '",Tableau6[[#This Row],[Référence]],"' where id = ",Tableau6[[#This Row],[id]]),"") -> update aocr_ref_arbo set reglementation = 'Décret n° 93-40 du 11 janvier 1993 relatif aux prescriptions techniques applicables à l''utilisation des équipements de travail soumis à l''article L 233-5-1 du code du travail, aux règles techniques applicables aux matériels d''occasion soumis à l''article L 233-5 du même code et à la mise en conformité des équipements existants et modifiant le code du travail (deuxième partie : Décrets en Conseil d''Etat).; Arrêté du 1er mars 2004 relatif aux vérifications des appareils et accessoires de levage Article 3' where id = 1906
A4: 542 | B4: Accessoire de levage | C4: Notice | D4: Accessoire de levage CE : L''exploitant doit posséder une notice de l''équipement décrivant les instructions d''utilisation, de maintenance, plans, etc. | F4: Article 3 Arrêté du 1er mars 2004 relatif aux vérifications des appareils et accessoires de levage; | H4: Ecart Détecté | I4: Fabricant | M4: 1 | N4: 1 | O4: 1 | P4: 0 | Q4: =#REF! -> #REF! | R4: =#REF! -> #REF! | S4: 1 | T4: 5 | V4: Propriétaire | Y4: =VLOOKUP(A8,Feuil1!A:B,2,FALSE) -> 421 | Z4: =VLOOKUP(A8,Feuil1!A:C,3,FALSE) -> 524 | AA4: =CONCATENATE("insert into AOCR_ref_arbo (libelle,reglementation,typologie,pere,commentaires,personne_habilitee,type_cont,pere_superieur,criticite) values ('",Tableau6[[#This Row],[Obligation]],"','",Tableau6[[#This Row],[Référence]],"',1,",Tableau6[[#This Row],[ID Domaine2]],",'",Tableau6[[#This Row],[Libellé détaillé]],"','",Tableau6[[#This Row],[Possible réalisateur]],"',3,",Tableau6[[#This Row],[ID Domaine]],",",Tableau6[[#This Row],[Urgence]],")") -> #REF! | AB4: =CONCATENATE("update aocr_ref_arbo set libelle = '",Tableau6[[#This Row],[Obligation]],"', reglementation = '",Tableau6[[#This Row],[Référence]],"', commentaires = '",Tableau6[[#This Row],[Libellé détaillé]],"', personne_habilitee = '",Tableau6[[#This Row],[Possible réalisateur]],"', criticite = ",Tableau6[[#This Row],[Urgence]]," where id = ",Tableau6[[#This Row],[id]]) -> update aocr_ref_arbo set libelle = 'Accessoire de levage CE : L''exploitant doit posséder une notice de l''équipement décrivant les instructions d''utilisation, de maintenance, plans, etc. ', reglementation = 'Article 3 Arrêté du 1er mars 2004 relatif aux vérifications des appareils et accessoires de levage;', commentaires = '', personne_habilitee = 'Fabricant', criticite = 5 where id = 542 | AC4: =IF(Tableau6[[#This Row],[Référence]]<>"",CONCATENATE("update aocr_ref_arbo set reglementation = '",Tableau6[[#This Row],[Référence]],"' where id = ",Tableau6[[#This Row],[id]]),"") -> update aocr_ref_arbo set reglementation = 'Article 3 Arrêté du 1er mars 2004 relatif aux vérifications des appareils et accessoires de levage;' where id = 542
A5: 539 | B5: Accessoire de levage | C5: Registre de sécurité | D5: Accessoire de levage : Registre de sécurité Les résultats des vérifications, des contrôles et des maintenances doivent être portés sur le registre sécurité. | F5: Code de la construction et de l''habitation Article R123-51 Code de la construction et de l''habitation Article R122-29 Code du travail Article L4711-5 Code du travail Article R4323-26 Article 3 Arrêté du 1er mars 2004 relatif aux vérifications des appareils et accessoires de levage. | H5: Ecart Détecté | I5: Exploitant | M5: 1 | N5: 1 | O5: 1 | P5: 0 | Q5: =#REF! -> #REF! | R5: =#REF! -> #REF! | S5: 1 | T5: 4 | V5: Locataire / Utilisateur | Y5: =VLOOKUP(A9,Feuil1!A:B,2,FALSE) -> 421 | Z5: =VLOOKUP(A9,Feuil1!A:C,3,FALSE) -> 1608 | AA5: =CONCATENATE("insert into AOCR_ref_arbo (libelle,reglementation,typologie,pere,commentaires,personne_habilitee,type_cont,pere_superieur,criticite) values ('",Tableau6[[#This Row],[Obligation]],"','",Tableau6[[#This Row],[Référence]],"',1,",Tableau6[[#This Row],[ID Domaine2]],",'",Tableau6[[#This Row],[Libellé détaillé]],"','",Tableau6[[#This Row],[Possible réalisateur]],"',3,",Tableau6[[#This Row],[ID Domaine]],",",Tableau6[[#This Row],[Urgence]],")") -> #REF! | AB5: =CONCATENATE("update aocr_ref_arbo set libelle = '",Tableau6[[#This Row],[Obligation]],"', reglementation = '",Tableau6[[#This Row],[Référence]],"', commentaires = '",Tableau6[[#This Row],[Libellé détaillé]],"', personne_habilitee = '",Tableau6[[#This Row],[Possible réalisateur]],"', criticite = ",Tableau6[[#This Row],[Urgence]]," where id = ",Tableau6[[#This Row],[id]]) -> update aocr_ref_arbo set libelle = 'Accessoire de levage : Registre de sécurité Les résultats des vérifications, des contrôles et des maintenances doivent être portés sur le registre sécurité.', reglementation = 'Code de la construction et de l''habitation Article R123-51 Code de la construction et de l''habitation Article R122-29 Code du travail Article L4711-5 Code du travail Article R4323-26 Article 3 Arrêté du 1er mars 2004 relatif aux vérifications des appareils et accessoires de levage.', commentaires = '', personne_habilitee = 'Exploitant', criticite = 4 where id = 539 | AC5: =IF(Tableau6[[#This Row],[Référence]]<>"",CONCATENATE("update aocr_ref_arbo set reglementation = '",Tableau6[[#This Row],[Référence]],"' where id = ",Tableau6[[#This Row],[id]]),"") -> update aocr_ref_arbo set reglementation = 'Code de la construction et de l''habitation Article R123-51 Code de la construction et de l''habitation Article R122-29 Code du travail Article L4711-5 Code du travail Article R4323-26 Article 3 Arrêté du 1er mars 2004 relatif aux vérifications des appareils et accessoires de levage.' where id = 539
A6: 533 | B6: Accessoire de levage | C6: Vérification à la mise en service | D6: Accessoires de levage neufs dont le responsable de la mise sur le marché s''est assuré de l''aptitude à l''emploi Aimant permanent, anneau, araignée, cé, crochet, élingue, manille, palonnier, pince, préhenseur, sangle. Examen d''adéquation | F6: Arrêté du 1 mars 2004 relatif aux vérifications des appareils et accessoires de levage Article 16 | H6: Ecart Détecté | I6: Personne qualifiée | M6: 1 | N6: 1 | O6: 1 | P6: 0 | Q6: =Y2 -> 421 | R6: =Z2 -> 524 | S6: 1 | T6: 5 | V6: Propriétaire | Y6: =VLOOKUP(A10,Feuil1!A:B,2,FALSE) -> 1285 | Z6: =VLOOKUP(A10,Feuil1!A:C,3,FALSE) -> 3771 | AA6: =CONCATENATE("insert into AOCR_ref_arbo (libelle,reglementation,typologie,pere,commentaires,personne_habilitee,type_cont,pere_superieur,criticite) values ('",Tableau6[[#This Row],[Obligation]],"','",Tableau6[[#This Row],[Référence]],"',1,",Tableau6[[#This Row],[ID Domaine2]],",'",Tableau6[[#This Row],[Libellé détaillé]],"','",Tableau6[[#This Row],[Possible réalisateur]],"',3,",Tableau6[[#This Row],[ID Domaine]],",",Tableau6[[#This Row],[Urgence]],")") -> insert into AOCR_ref_arbo (libelle,reglementation,typologie,pere,commentaires,personne_habilitee,type_cont,pere_superieur,criticite) values ('Accessoires de levage neufs dont le responsable de la mise sur le marché s''est assuré de l''aptitude à l''emploi Aimant permanent, anneau, araignée, cé, crochet, élingue, manille, palonnier, pince, préhenseur, sangle. Examen d''adéquation','Arrêté du 1 mars 2004 relatif aux vérifications des appareils et accessoires de levage Article 16',1,524,'','Personne qualifiée',3,421,5) | AB6: =CONCATENATE("update aocr_ref_arbo set libelle = '",Tableau6[[#This Row],[Obligation]],"', reglementation = '",Tableau6[[#This Row],[Référence]],"', commentaires = '",Tableau6[[#This Row],[Libellé détaillé]],"', personne_habilitee = '",Tableau6[[#This Row],[Possible réalisateur]],"', criticite = ",Tableau6[[#This Row],[Urgence]]," where id = ",Tableau6[[#This Row],[id]]) -> update aocr_ref_arbo set libelle = 'Accessoires de levage neufs dont le responsable de la mise sur le marché s''est assuré de l''aptitude à l''emploi Aimant permanent, anneau, araignée, cé, crochet, élingue, manille, palonnier, pince, préhenseur, sangle. Examen d''adéquation', reglementation = 'Arrêté du 1 mars 2004 relatif aux vérifications des appareils et accessoires de levage Article 16', commentaires = '', personne_habilitee = 'Personne qualifiée', criticite = 5 where id = 533 | AC6: =IF(Tableau6[[#This Row],[Référence]]<>"",CONCATENATE("update aocr_ref_arbo set reglementation = '",Tableau6[[#This Row],[Référence]],"' where id = ",Tableau6[[#This Row],[id]]),"") -> update aocr_ref_arbo set reglementation = 'Arrêté du 1 mars 2004 relatif aux vérifications des appareils et accessoires de levage Article 16' where id = 533
A7: 534 | B7: Accessoire de levage | C7: Vérification à la mise en service | D7: Accessoires de levage neufs dont le responsable de la mise sur le marché ne s''est pas assuré de l''aptitude à l''emploi ou accesoires d''occasion Aimant permanent, anneau, araignée, cé, crochet, élingue, manille, palonnier, pince, préhenseur, sangle. Examen d''adéquation / Épreuve statique | F7: Arrêté du 1 mars 2004 relatif aux vérifications des appareils et accessoires de levage Article 17 | H7: Ecart Détecté | I7: Personne qualifiée | M7: 1 | N7: 1 | O7: 1 | P7: 0 | Q7: =Y3 -> 421 | R7: =Z3 -> 524 | S7: 1 | T7: 5 | V7: Propriétaire | Y7: =VLOOKUP(A11,Feuil1!A:B,2,FALSE) -> 1285 | Z7: =VLOOKUP(A11,Feuil1!A:C,3,FALSE) -> 1287 | AA7: =CONCATENATE("insert into AOCR_ref_arbo (libelle,reglementation,typologie,pere,commentaires,personne_habilitee,type_cont,pere_superieur,criticite) values ('",Tableau6[[#This Row],[Obligation]],"','",Tableau6[[#This Row],[Référence]],"',1,",Tableau6[[#This Row],[ID Domaine2]],",'",Tableau6[[#This Row],[Libellé détaillé]],"','",Tableau6[[#This Row],[Possible réalisateur]],"',3,",Tableau6[[#This Row],[ID Domaine]],",",Tableau6[[#This Row],[Urgence]],")") -> insert into AOCR_ref_arbo (libelle,reglementation,typologie,pere,commentaires,personne_habilitee,type_cont,pere_superieur,criticite) values ('Accessoires de levage neufs dont le responsable de la mise sur le marché ne s''est pas assuré de l''aptitude à l''emploi ou accesoires d''occasion Aimant permanent, anneau, araignée, cé, crochet, élingue, manille, palonnier, pince, préhenseur, sangle. Examen d''adéquation / Épreuve statique','Arrêté du 1 mars 2004 relatif aux vérifications des appareils et accessoires de levage Article 17',1,524,'','Personne qualifiée',3,421,5) | AB7: =CONCATENATE("update aocr_ref_arbo set libelle = '",Tableau6[[#This Row],[Obligation]],"', reglementation = '",Tableau6[[#This Row],[Référence]],"', commentaires = '",Tableau6[[#This Row],[Libellé détaillé]],"', personne_habilitee = '",Tableau6[[#This Row],[Possible réalisateur]],"', criticite = ",Tableau6[[#This Row],[Urgence]]," where id = ",Tableau6[[#This Row],[id]]) -> update aocr_ref_arbo set libelle = 'Accessoires de levage neufs dont le responsable de la mise sur le marché ne s''est pas assuré de l''aptitude à l''emploi ou accesoires d''occasion Aimant permanent, anneau, araignée, cé, crochet, élingue, manille, palonnier, pince, préhenseur, sangle. Examen d''adéquation / Épreuve statique', reglementation = 'Arrêté du 1 mars 2004 relatif aux vérifications des appareils et accessoires de levage Article 17', commentaires = '', personne_habilitee = 'Personne qualifiée', criticite = 5 where id = 534 | AC7: =IF(Tableau6[[#This Row],[Référence]]<>"",CONCATENATE("update aocr_ref_arbo set reglementation = '",Tableau6[[#This Row],[Référence]],"' where id = ",Tableau6[[#This Row],[id]]),"") -> update aocr_ref_arbo set reglementation = 'Arrêté du 1 mars 2004 relatif aux vérifications des appareils et accessoires de levage Article 17' where id = 534
A8: 1288 | B8: Accessoire de levage | C8: Vérification à la mise en service | D8: Accessoire de levage CE : Vérification à la mise en service - Aptitude à l''emploi L''aptitude à l''emploi doit être réalisée. Elle mentionne l''épreuve statique de l''équipement. | F8: Arrêté du 1 mars 2004 relatif aux vérifications des appareils et accessoires de levage Article 16; | H8: Ecart Détecté | I8: Personne qualifiée | M8: 1 | N8: 1 | O8: 1 | P8: 0 | Q8: =Y4 -> 421 | R8: =Z4 -> 524 | S8: 1 | T8: 5 | V8: Propriétaire | Y8: =VLOOKUP(A12,Feuil1!A:B,2,FALSE) -> 1285 | Z8: =VLOOKUP(A12,Feuil1!A:C,3,FALSE) -> 1287 | AA8: =CONCATENATE("insert into AOCR_ref_arbo (libelle,reglementation,typologie,pere,commentaires,personne_habilitee,type_cont,pere_superieur,criticite) values ('",Tableau6[[#This Row],[Obligation]],"','",Tableau6[[#This Row],[Référence]],"',1,",Tableau6[[#This Row],[ID Domaine2]],",'",Tableau6[[#This Row],[Libellé détaillé]],"','",Tableau6[[#This Row],[Possible réalisateur]],"',3,",Tableau6[[#This Row],[ID Domaine]],",",Tableau6[[#This Row],[Urgence]],")") -> insert into AOCR_ref_arbo (libelle,reglementation,typologie,pere,commentaires,personne_habilitee,type_cont,pere_superieur,criticite) values ('Accessoire de levage CE : Vérification à la mise en service - Aptitude à l''emploi L''aptitude à l''emploi doit être réalisée. Elle mentionne l''épreuve statique de l''équipement.','Arrêté du 1 mars 2004 relatif aux vérifications des appareils et accessoires de levage Article 16;',1,524,'','Personne qualifiée',3,421,5) | AB8: =CONCATENATE("update aocr_ref_arbo set libelle = '",Tableau6[[#This Row],[Obligation]],"', reglementation = '",Tableau6[[#This Row],[Référence]],"', commentaires = '",Tableau6[[#This Row],[Libellé détaillé]],"', personne_habilitee = '",Tableau6[[#This Row],[Possible réalisateur]],"', criticite = ",Tableau6[[#This Row],[Urgence]]," where id = ",Tableau6[[#This Row],[id]]) -> update aocr_ref_arbo set libelle = 'Accessoire de levage CE : Vérification à la mise en service - Aptitude à l''emploi L''aptitude à l''emploi doit être réalisée. Elle mentionne l''épreuve statique de l''équipement.', reglementation = 'Arrêté du 1 mars 2004 relatif aux vérifications des appareils et accessoires de levage Article 16;', commentaires = '', personne_habilitee = 'Personne qualifiée', criticite = 5 where id = 1288 | AC8: =IF(Tableau6[[#This Row],[Référence]]<>"",CONCATENATE("update aocr_ref_arbo set reglementation = '",Tableau6[[#This Row],[Référence]],"' where id = ",Tableau6[[#This Row],[id]]),"") -> update aocr_ref_arbo set reglementation = 'Arrêté du 1 mars 2004 relatif aux vérifications des appareils et accessoires de levage Article 16;' where id = 1288
A9: 530 | B9: Accessoire de levage | C9: Vérification Périodique 1 an | D9: Accessoire de levage : Vérification Périodique annuelle | E9: Le périmètre de vos équipements contrôlés doit correspondre à votre parc d''appareils soumis à contrôle. Les observations issues des vérifications doivent être traitées / Article R4323-26 : Lorsque les vérifications périodiques sont réalisées par des personnes n''appartenant pas à l''établissement, les rapports établis à la suite de ces vérifications sont annexés au registre de sécurité. Les indications précises relatives à la date des vérifications, à la date de remise des rapports correspondants et à leur archivage dans l''établissement sont portées sur le registre de sécurité. | F9: Arrêté du 1 mars 2004 relatif aux vérifications des appareils et accessoires de levage Article 24 | H9: Ecart Détecté | I9: Personne qualifiée | M9: 1 | N9: 1 | O9: 1 | P9: 0 | Q9: =Y5 -> 421 | R9: =Z5 -> 1608 | S9: 1 | T9: 4 | V9: Locataire / Utilisateur | Y9: =VLOOKUP(A13,Feuil1!A:B,2,FALSE) -> 1285 | Z9: =VLOOKUP(A13,Feuil1!A:C,3,FALSE) -> 1287 | AA9: =CONCATENATE("insert into AOCR_ref_arbo (libelle,reglementation,typologie,pere,commentaires,personne_habilitee,type_cont,pere_superieur,criticite) values ('",Tableau6[[#This Row],[Obligation]],"','",Tableau6[[#This Row],[Référence]],"',1,",Tableau6[[#This Row],[ID Domaine2]],",'",Tableau6[[#This Row],[Libellé détaillé]],"','",Tableau6[[#This Row],[Possible réalisateur]],"',3,",Tableau6[[#This Row],[ID Domaine]],",",Tableau6[[#This Row],[Urgence]],")") -> insert into AOCR_ref_arbo (libelle,reglementation,typologie,pere,commentaires,personne_habilitee,type_cont,pere_superieur,criticite) values ('Accessoire de levage : Vérification Périodique annuelle','Arrêté du 1 mars 2004 relatif aux vérifications des appareils et accessoires de levage Article 24',1,1608,' Le périmètre de vos équipements contrôlés doit correspondre à votre parc d''appareils soumis à contrôle. Les observations issues des vérifications doivent être traitées / Article R4323-26 : Lorsque les vérifications périodiques sont réalisées par des personnes n''appartenant pas à l''établissement, les rapports établis à la suite de ces vérifications sont annexés au registre de sécurité. Les indications précises relatives à la date des vérifications, à la date de remise des rapports correspondants et à leur archivage dans l''établissement sont portées sur le registre de sécurité.','Personne qualifiée',3,421,4) | AB9: =CONCATENATE("update aocr_ref_arbo set libelle = '",Tableau6[[#This Row],[Obligation]],"', reglementation = '",Tableau6[[#This Row],[Référence]],"', commentaires = '",Tableau6[[#This Row],[Libellé détaillé]],"', personne_habilitee = '",Tableau6[[#This Row],[Possible réalisateur]],"', criticite = ",Tableau6[[#This Row],[Urgence]]," where id = ",Tableau6[[#This Row],[id]]) -> update aocr_ref_arbo set libelle = 'Accessoire de levage : Vérification Périodique annuelle', reglementation = 'Arrêté du 1 mars 2004 relatif aux vérifications des appareils et accessoires de levage Article 24', commentaires = ' Le périmètre de vos équipements contrôlés doit correspondre à votre parc d''appareils soumis à contrôle. Les observations issues des vérifications doivent être traitées / Article R4323-26 : Lorsque les vérifications périodiques sont réalisées par des personnes n''appartenant pas à l''établissement, les rapports établis à la suite de ces vérifications sont annexés au registre de sécurité. Les indications précises relatives à la date des vérifications, à la date de remise des rapports correspondants et à leur archivage dans l''établissement sont portées sur le registre de sécurité.', personne_habilitee = 'Personne qualifiée', criticite = 4 where id = 530 | AC9: =IF(Tableau6[[#This Row],[Référence]]<>"",CONCATENATE("update aocr_ref_arbo set reglementation = '",Tableau6[[#This Row],[Référence]],"' where id = ",Tableau6[[#This Row],[id]]),"") -> update aocr_ref_arbo set reglementation = 'Arrêté du 1 mars 2004 relatif aux vérifications des appareils et accessoires de levage Article 24' where id = 530
A10: 3780 | B10: Aération et ventilation | C10: Contrat de maintenance | D10: VMC-Gaz : Contrat de maintenance | E10: Le propriétaire ou le syndic d'un immeuble équipé d'installations collectives de ventilation mécanique contrôlée auxquelles sont raccordés des appareils à gaz (ventilation mécanique contrôlée - gaz) est tenu de faire entretenir et vérifier périodiquement l'ensemble de ces installations et d'en assurer la maintenance aux termes de contrats écrits faisant référence au présent arrêté passés avec un ou plusieurs professionnels qualifiés. | F10: A. du 25-04-1985(1), art. 1 | H10: Ecart Détecté | P10: 0 | Q10: =Y6 -> 1285 | R10: =Z6 -> 3771 | T10: 4 | V10: Propriétaire | Y10: =VLOOKUP(A14,Feuil1!A:B,2,FALSE) -> 1285 | Z10: =VLOOKUP(A14,Feuil1!A:C,3,FALSE) -> 1286 | AA10: =CONCATENATE("insert into AOCR_ref_arbo (libelle,reglementation,typologie,pere,commentaires,personne_habilitee,type_cont,pere_superieur,criticite) values ('",Tableau6[[#This Row],[Obligation]],"','",Tableau6[[#This Row],[Référence]],"',1,",Tableau6[[#This Row],[ID Domaine2]],",'",Tableau6[[#This Row],[Libellé détaillé]],"','",Tableau6[[#This Row],[Possible réalisateur]],"',3,",Tableau6[[#This Row],[ID Domaine]],",",Tableau6[[#This Row],[Urgence]],")") -> insert into AOCR_ref_arbo (libelle,reglementation,typologie,pere,commentaires,personne_habilitee,type_cont,pere_superieur,criticite) values ('VMC-Gaz : Contrat de maintenance','A. du 25-04-1985(1), art. 1 ',1,3771,'Le propriétaire ou le syndic d'un immeuble équipé d'installations collectives de ventilation mécanique contrôlée auxquelles sont raccordés des appareils à gaz (ventilation mécanique contrôlée - gaz) est tenu de faire entretenir et vérifier périodiquement l'ensemble de ces installations et d'en assurer la maintenance aux termes de contrats écrits faisant référence au présent arrêté passés avec un ou plusieurs professionnels qualifiés.','',3,1285,4) | AB10: =CONCATENATE("update aocr_ref_arbo set libelle = '",Tableau6[[#This Row],[Obligation]],"', reglementation = '",Tableau6[[#This Row],[Référence]],"', commentaires = '",Tableau6[[#This Row],[Libellé détaillé]],"', personne_habilitee = '",Tableau6[[#This Row],[Possible réalisateur]],"', criticite = ",Tableau6[[#This Row],[Urgence]]," where id = ",Tableau6[[#This Row],[id]]) -> update aocr_ref_arbo set libelle = 'VMC-Gaz : Contrat de maintenance', reglementation = 'A. du 25-04-1985(1), art. 1 ', commentaires = 'Le propriétaire ou le syndic d'un immeuble équipé d'installations collectives de ventilation mécanique contrôlée auxquelles sont raccordés des appareils à gaz (ventilation mécanique contrôlée - gaz) est tenu de faire entretenir et vérifier périodiquement l'ensemble de ces installations et d'en assurer la maintenance aux termes de contrats écrits faisant référence au présent arrêté passés avec un ou plusieurs professionnels qualifiés.', personne_habilitee = '', criticite = 4 where id = 3780 | AC10: =IF(Tableau6[[#This Row],[Référence]]<>"",CONCATENATE("update aocr_ref_arbo set reglementation = '",Tableau6[[#This Row],[Référence]],"' where id = ",Tableau6[[#This Row],[id]]),"") -> update aocr_ref_arbo set reglementation = 'A. du 25-04-1985(1), art. 1 ' where id = 3780
A11: 1292 | B11: Aération et ventilation | C11: Établissement Recevant du Public (ERP) | D11: Aération et ventilation : Locaux à pollution spécifique et non spécifique ERP : Vérification périodique - Rapport de Vérification | E11: Personne compétente | F11: Arrêté du 25 juin 1980 portant approbation des dispositions générales du règlement de sécurité contre les risques d''incendie et de panique dans les établissements recevant du public (ERP). Article CH 58; | H11: Ecart Détecté | M11: 0 | N11: 0 | O11: 1 | P11: 0 | Q11: =Y7 -> 1285 | R11: =Z7 -> 1287 | S11: 1 | T11: 5 | V11: Propriétaire | Y11: =VLOOKUP(A15,Feuil1!A:B,2,FALSE) -> 1285 | Z11: =VLOOKUP(A15,Feuil1!A:C,3,FALSE) -> 2199 | AA11: =CONCATENATE("insert into AOCR_ref_arbo (libelle,reglementation,typologie,pere,commentaires,personne_habilitee,type_cont,pere_superieur,criticite) values ('",Tableau6[[#This Row],[Obligation]],"','",Tableau6[[#This Row],[Référence]],"',1,",Tableau6[[#This Row],[ID Domaine2]],",'",Tableau6[[#This Row],[Libellé détaillé]],"','",Tableau6[[#This Row],[Possible réalisateur]],"',3,",Tableau6[[#This Row],[ID Domaine]],",",Tableau6[[#This Row],[Urgence]],")") -> insert into AOCR_ref_arbo (libelle,reglementation,typologie,pere,commentaires,personne_habilitee,type_cont,pere_superieur,criticite) values ('Aération et ventilation : Locaux à pollution spécifique et non spécifique ERP : Vérification périodique - Rapport de Vérification','Arrêté du 25 juin 1980 portant approbation des dispositions générales du règlement de sécurité contre les risques d''incendie et de panique dans les établissements recevant du public (ERP). Article CH 58;',1,1287,'Personne compétente','',3,1285,5) | AB11: =CONCATENATE("update aocr_ref_arbo set libelle = '",Tableau6[[#This Row],[Obligation]],"', reglementation = '",Tableau6[[#This Row],[Référence]],"', commentaires = '",Tableau6[[#This Row],[Libellé détaillé]],"', personne_habilitee = '",Tableau6[[#This Row],[Possible réalisateur]],"', criticite = ",Tableau6[[#This Row],[Urgence]]," where id = ",Tableau6[[#This Row],[id]]) -> update aocr_ref_arbo set libelle = 'Aération et ventilation : Locaux à pollution spécifique et non spécifique ERP : Vérification périodique - Rapport de Vérification', reglementation = 'Arrêté du 25 juin 1980 portant approbation des dispositions générales du règlement de sécurité contre les risques d''incendie et de panique dans les établissements recevant du public (ERP). Article CH 58;', commentaires = 'Personne compétente', personne_habilitee = '', criticite = 5 where id = 1292 | AC11: =IF(Tableau6[[#This Row],[Référence]]<>"",CONCATENATE("update aocr_ref_arbo set reglementation = '",Tableau6[[#This Row],[Référence]],"' where id = ",Tableau6[[#This Row],[id]]),"") -> update aocr_ref_arbo set reglementation = 'Arrêté du 25 juin 1980 portant approbation des dispositions générales du règlement de sécurité contre les risques d''incendie et de panique dans les établissements recevant du public (ERP). Article CH 58;' where id = 1292
A12: 1293 | B12: Aération et ventilation | C12: Établissement Recevant du Public (ERP) | D12: Aération et ventilation : Dispositifs de surveillance de la qualité de l''air Parcs de stationnement couverts ERP inférieur ou égale à 250 véhicules : Contrôle biennale | F12: Arrêté du 25 juin 1980 Article PS 32 | H12: Ecart Détecté | M12: 0 | N12: 0 | O12: 1 | P12: 0 | Q12: =Y8 -> 1285 | R12: =Z8 -> 1287 | S12: 1 | T12: 5 | V12: Propriétaire | Y12: =VLOOKUP(A16,Feuil1!A:B,2,FALSE) -> 1285 | Z12: =VLOOKUP(A16,Feuil1!A:C,3,FALSE) -> 1739 | AA12: =CONCATENATE("insert into AOCR_ref_arbo (libelle,reglementation,typologie,pere,commentaires,personne_habilitee,type_cont,pere_superieur,criticite) values ('",Tableau6[[#This Row],[Obligation]],"','",Tableau6[[#This Row],[Référence]],"',1,",Tableau6[[#This Row],[ID Domaine2]],",'",Tableau6[[#This Row],[Libellé détaillé]],"','",Tableau6[[#This Row],[Possible réalisateur]],"',3,",Tableau6[[#This Row],[ID Domaine]],",",Tableau6[[#This Row],[Urgence]],")") -> insert into AOCR_ref_arbo (libelle,reglementation,typologie,pere,commentaires,personne_habilitee,type_cont,pere_superieur,criticite) values ('Aération et ventilation : Dispositifs de surveillance de la qualité de l''air Parcs de stationnement couverts ERP inférieur ou égale à 250 véhicules : Contrôle biennale','Arrêté du 25 juin 1980 Article PS 32',1,1287,'','',3,1285,5) | AB12: =CONCATENATE("update aocr_ref_arbo set libelle = '",Tableau6[[#This Row],[Obligation]],"', reglementation = '",Tableau6[[#This Row],[Référence]],"', commentaires = '",Tableau6[[#This Row],[Libellé détaillé]],"', personne_habilitee = '",Tableau6[[#This Row],[Possible réalisateur]],"', criticite = ",Tableau6[[#This Row],[Urgence]]," where id = ",Tableau6[[#This Row],[id]]) -> update aocr_ref_arbo set libelle = 'Aération et ventilation : Dispositifs de surveillance de la qualité de l''air Parcs de stationnement couverts ERP inférieur ou égale à 250 véhicules : Contrôle biennale', reglementation = 'Arrêté du 25 juin 1980 Article PS 32', commentaires = '', personne_habilitee = '', criticite = 5 where id = 1293 | AC12: =IF(Tableau6[[#This Row],[Référence]]<>"",CONCATENATE("update aocr_ref_arbo set reglementation = '",Tableau6[[#This Row],[Référence]],"' where id = ",Tableau6[[#This Row],[id]]),"") -> update aocr_ref_arbo set reglementation = 'Arrêté du 25 juin 1980 Article PS 32' where id = 1293
A13: 1294 | B13: Aération et ventilation | C13: Établissement Recevant du Public (ERP) | D13: Aération et ventilation : Dispositifs de surveillance de la qualité de l''air Parcs de stationnement couverts ERP supérieur à 250 véhicules : Contrôle annuel | F13: Arrêté du 25 juin 1980 Article PS 32 | H13: Ecart Détecté | M13: 0 | N13: 0 | O13: 1 | P13: 0 | Q13: =Y9 -> 1285 | R13: =Z9 -> 1287 | S13: 1 | T13: 4 | V13: Locataire / Utilisateur | Y13: =VLOOKUP(A17,Feuil1!A:B,2,FALSE) -> 1285 | Z13: =VLOOKUP(A17,Feuil1!A:C,3,FALSE) -> 1739 | AA13: =CONCATENATE("insert into AOCR_ref_arbo (libelle,reglementation,typologie,pere,commentaires,personne_habilitee,type_cont,pere_superieur,criticite) values ('",Tableau6[[#This Row],[Obligation]],"','",Tableau6[[#This Row],[Référence]],"',1,",Tableau6[[#This Row],[ID Domaine2]],",'",Tableau6[[#This Row],[Libellé détaillé]],"','",Tableau6[[#This Row],[Possible réalisateur]],"',3,",Tableau6[[#This Row],[ID Domaine]],",",Tableau6[[#This Row],[Urgence]],")") -> insert into AOCR_ref_arbo (libelle,reglementation,typologie,pere,commentaires,personne_habilitee,type_cont,pere_superieur,criticite) values ('Aération et ventilation : Dispositifs de surveillance de la qualité de l''air Parcs de stationnement couverts ERP supérieur à 250 véhicules : Contrôle annuel','Arrêté du 25 juin 1980 Article PS 32',1,1287,'','',3,1285,4) | AB13: =CONCATENATE("update aocr_ref_arbo set libelle = '",Tableau6[[#This Row],[Obligation]],"', reglementation = '",Tableau6[[#This Row],[Référence]],"', commentaires = '",Tableau6[[#This Row],[Libellé détaillé]],"', personne_habilitee = '",Tableau6[[#This Row],[Possible réalisateur]],"', criticite = ",Tableau6[[#This Row],[Urgence]]," where id = ",Tableau6[[#This Row],[id]]) -> update aocr_ref_arbo set libelle = 'Aération et ventilation : Dispositifs de surveillance de la qualité de l''air Parcs de stationnement couverts ERP supérieur à 250 véhicules : Contrôle annuel', reglementation = 'Arrêté du 25 juin 1980 Article PS 32', commentaires = '', personne_habilitee = '', criticite = 4 where id = 1294 | AC13: =IF(Tableau6[[#This Row],[Référence]]<>"",CONCATENATE("update aocr_ref_arbo set reglementation = '",Tableau6[[#This Row],[Référence]],"' where id = ",Tableau6[[#This Row],[id]]),"") -> update aocr_ref_arbo set reglementation = 'Arrêté du 25 juin 1980 Article PS 32' where id = 1294
A14: 1289 | B14: Aération et ventilation | C14: Immeuble de Grande Hauteur (IGH) | D14: Aération et ventilation : Locaux à pollution spécifique et non spécifique IGH : Contrôle à la Mise en Service Rapport de Vérification Réglementaire Après Travaux (RVRAT) | F14: Arrêté du 30 décembre 2011 portant règlement de sécurité pour la construction des immeubles de grande hauteur et leur protection contre les risques d''incendie et de panique Article GH 5 § 2.; Arrêté du 25 juin 1980 portant approbation des dispositions générales du règlement de sécurité contre les risques d''incendie et de panique dans les établissements recevant du public (ERP). Article CH 58; | H14: Ecart Détecté | M14: 0 | N14: 0 | O14: 1 | P14: 0 | Q14: =Y10 -> 1285 | R14: =Z10 -> 1286 | S14: 1 | T14: 5 | V14: Propriétaire | Y14: =VLOOKUP(A18,Feuil1!A:B,2,FALSE) -> 1285 | Z14: =VLOOKUP(A18,Feuil1!A:C,3,FALSE) -> 1740 | AA14: =CONCATENATE("insert into AOCR_ref_arbo (libelle,reglementation,typologie,pere,commentaires,personne_habilitee,type_cont,pere_superieur,criticite) values ('",Tableau6[[#This Row],[Obligation]],"','",Tableau6[[#This Row],[Référence]],"',1,",Tableau6[[#This Row],[ID Domaine2]],",'",Tableau6[[#This Row],[Libellé détaillé]],"','",Tableau6[[#This Row],[Possible réalisateur]],"',3,",Tableau6[[#This Row],[ID Domaine]],",",Tableau6[[#This Row],[Urgence]],")") -> insert into AOCR_ref_arbo (libelle,reglementation,typologie,pere,commentaires,personne_habilitee,type_cont,pere_superieur,criticite) values ('Aération et ventilation : Locaux à pollution spécifique et non spécifique IGH : Contrôle à la Mise en Service Rapport de Vérification Réglementaire Après Travaux (RVRAT)','Arrêté du 30 décembre 2011 portant règlement de sécurité pour la construction des immeubles de grande hauteur et leur protection contre les risques d''incendie et de panique Article GH 5 § 2.; Arrêté du 25 juin 1980 portant approbation des dispositions générales du règlement de sécurité contre les risques d''incendie et de panique dans les établissements recevant du public (ERP). Article CH 58;',1,1286,'','',3,1285,5) | AB14: =CONCATENATE("update aocr_ref_arbo set libelle = '",Tableau6[[#This Row],[Obligation]],"', reglementation = '",Tableau6[[#This Row],[Référence]],"', commentaires = '",Tableau6[[#This Row],[Libellé détaillé]],"', personne_habilitee = '",Tableau6[[#This Row],[Possible réalisateur]],"', criticite = ",Tableau6[[#This Row],[Urgence]]," where id = ",Tableau6[[#This Row],[id]]) -> update aocr_ref_arbo set libelle = 'Aération et ventilation : Locaux à pollution spécifique et non spécifique IGH : Contrôle à la Mise en Service Rapport de Vérification Réglementaire Après Travaux (RVRAT)', reglementation = 'Arrêté du 30 décembre 2011 portant règlement de sécurité pour la construction des immeubles de grande hauteur et leur protection contre les risques d''incendie et de panique Article GH 5 § 2.; Arrêté du 25 juin 1980 portant approbation des dispositions générales du règlement de sécurité contre les risques d''incendie et de panique dans les établissements recevant du public (ERP). Article CH 58;', commentaires = '', personne_habilitee = '', criticite = 5 where id = 1289 | AC14: =IF(Tableau6[[#This Row],[Référence]]<>"",CONCATENATE("update aocr_ref_arbo set reglementation = '",Tableau6[[#This Row],[Référence]],"' where id = ",Tableau6[[#This Row],[id]]),"") -> update aocr_ref_arbo set reglementation = 'Arrêté du 30 décembre 2011 portant règlement de sécurité pour la construction des immeubles de grande hauteur et leur protection contre les risques d''incendie et de panique Article GH 5 § 2.; Arrêté du 25 juin 1980 portant approbation des dispositions générales du règlement de sécurité contre les risques d''incendie et de panique dans les établissements recevant du public (ERP). Article CH 58;' where id = 1289
A15: 2203 | B15: Aération et ventilation | C15: Registre de sécurité | D15: Aération et ventilation : Registre de sécurité Les résultats des vérifications, des contrôles et des maintenances doivent être portés sur le registre sécurité. | F15: Code de la construction et de l''habitation Article R123-51 Code de la construction et de l''habitation Article R122-29 Code du travail Article L4711-5 Code du travail Article R4323-26 Article 3 Arrêté du 1er mars 2004 Arrêté du 08-10-1987, art. 2 | H15: Ecart Détecté | M15: 1 | N15: 1 | O15: 1 | P15: 0 | Q15: =Y11 -> 1285 | R15: =Z11 -> 2199 | S15: 1 | T15: 4 | V15: Locataire / Utilisateur | Y15: =VLOOKUP(A19,Feuil1!A:B,2,FALSE) -> 1285 | Z15: =VLOOKUP(A19,Feuil1!A:C,3,FALSE) -> 1740 | AA15: =CONCATENATE("insert into AOCR_ref_arbo (libelle,reglementation,typologie,pere,commentaires,personne_habilitee,type_cont,pere_superieur,criticite) values ('",Tableau6[[#This Row],[Obligation]],"','",Tableau6[[#This Row],[Référence]],"',1,",Tableau6[[#This Row],[ID Domaine2]],",'",Tableau6[[#This Row],[Libellé détaillé]],"','",Tableau6[[#This Row],[Possible réalisateur]],"',3,",Tableau6[[#This Row],[ID Domaine]],",",Tableau6[[#This Row],[Urgence]],")") -> insert into AOCR_ref_arbo (libelle,reglementation,typologie,pere,commentaires,personne_habilitee,type_cont,pere_superieur,criticite) values ('Aération et ventilation : Registre de sécurité Les résultats des vérifications, des contrôles et des maintenances doivent être portés sur le registre sécurité.','Code de la construction et de l''habitation Article R123-51 Code de la construction et de l''habitation Article R122-29 Code du travail Article L4711-5 Code du travail Article R4323-26 Article 3 Arrêté du 1er mars 2004 Arrêté du 08-10-1987, art. 2',1,2199,'','',3,1285,4) | AB15: =CONCATENATE("update aocr_ref_arbo set libelle = '",Tableau6[[#This Row],[Obligation]],"', reglementation = '",Tableau6[[#This Row],[Référence]],"', commentaires = '",Tableau6[[#This Row],[Libellé détaillé]],"', personne_habilitee = '",Tableau6[[#This Row],[Possible réalisateur]],"', criticite = ",Tableau6[[#This Row],[Urgence]]," where id = ",Tableau6[[#This Row],[id]]) -> update aocr_ref_arbo set libelle = 'Aération et ventilation : Registre de sécurité Les résultats des vérifications, des contrôles et des maintenances doivent être portés sur le registre sécurité.', reglementation = 'Code de la construction et de l''habitation Article R123-51 Code de la construction et de l''habitation Article R122-29 Code du travail Article L4711-5 Code du travail Article R4323-26 Article 3 Arrêté du 1er mars 2004 Arrêté du 08-10-1987, art. 2', commentaires = '', personne_habilitee = '', criticite = 4 where id = 2203 | AC15: =IF(Tableau6[[#This Row],[Référence]]<>"",CONCATENATE("update aocr_ref_arbo set reglementation = '",Tableau6[[#This Row],[Référence]],"' where id = ",Tableau6[[#This Row],[id]]),"") -> update aocr_ref_arbo set reglementation = 'Code de la construction et de l''habitation Article R123-51 Code de la construction et de l''habitation Article R122-29 Code du travail Article L4711-5 Code du travail Article R4323-26 Article 3 Arrêté du 1er mars 2004 Arrêté du 08-10-1987, art. 2' where id = 2203
A16: 1053 | B16: Aération et ventilation | C16: Vérification à la mise en service | D16: Aération et ventilation: Installation à pollution spécifique et non spécifique Vérification à la mise en service / Etablissement d''une notice d''instruction | E16: Des mesures, contrôles et examen doivent être effectué au plus tard un mois après la mise en service. | F16: CT. art. R. 4212-7 CT. art. R. 4212-3 CT. art. R. 4222-21 Arrêté du 08-10-1987, art. 2, 3 et 4. | H16: Ecart Détecté | M16: 1 | N16: 1 | O16: 1 | P16: 0 | Q16: =Y12 -> 1285 | R16: =Z12 -> 1739 | S16: 1 | T16: 5 | V16: Propriétaire | Y16: =VLOOKUP(A20,Feuil1!A:B,2,FALSE) -> 1285 | Z16: =VLOOKUP(A20,Feuil1!A:C,3,FALSE) -> 3770 | AA16: =CONCATENATE("insert into AOCR_ref_arbo (libelle,reglementation,typologie,pere,commentaires,personne_habilitee,type_cont,pere_superieur,criticite) values ('",Tableau6[[#This Row],[Obligation]],"','",Tableau6[[#This Row],[Référence]],"',1,",Tableau6[[#This Row],[ID Domaine2]],",'",Tableau6[[#This Row],[Libellé détaillé]],"','",Tableau6[[#This Row],[Possible réalisateur]],"',3,",Tableau6[[#This Row],[ID Domaine]],",",Tableau6[[#This Row],[Urgence]],")") -> insert into AOCR_ref_arbo (libelle,reglementation,typologie,pere,commentaires,personne_habilitee,type_cont,pere_superieur,criticite) values ('Aération et ventilation: Installation à pollution spécifique et non spécifique Vérification à la mise en service / Etablissement d''une notice d''instruction','CT. art. R. 4212-7 CT. art. R. 4212-3 CT. art. R. 4222-21 Arrêté du 08-10-1987, art. 2, 3 et 4. ',1,1739,'Des mesures, contrôles et examen doivent être effectué au plus tard un mois après la mise en service.','',3,1285,5) | AB16: =CONCATENATE("update aocr_ref_arbo set libelle = '",Tableau6[[#This Row],[Obligation]],"', reglementation = '",Tableau6[[#This Row],[Référence]],"', commentaires = '",Tableau6[[#This Row],[Libellé détaillé]],"', personne_habilitee = '",Tableau6[[#This Row],[Possible réalisateur]],"', criticite = ",Tableau6[[#This Row],[Urgence]]," where id = ",Tableau6[[#This Row],[id]]) -> update aocr_ref_arbo set libelle = 'Aération et ventilation: Installation à pollution spécifique et non spécifique Vérification à la mise en service / Etablissement d''une notice d''instruction', reglementation = 'CT. art. R. 4212-7 CT. art. R. 4212-3 CT. art. R. 4222-21 Arrêté du 08-10-1987, art. 2, 3 et 4. ', commentaires = 'Des mesures, contrôles et examen doivent être effectué au plus tard un mois après la mise en service.', personne_habilitee = '', criticite = 5 where id = 1053 | AC16: =IF(Tableau6[[#This Row],[Référence]]<>"",CONCATENATE("update aocr_ref_arbo set reglementation = '",Tableau6[[#This Row],[Référence]],"' where id = ",Tableau6[[#This Row],[id]]),"") -> update aocr_ref_arbo set reglementation = 'CT. art. R. 4212-7 CT. art. R. 4212-3 CT. art. R. 4222-21 Arrêté du 08-10-1987, art. 2, 3 et 4. ' where id = 1053
A17: 3702 | B17: Aération et ventilation | C17: Vérification à la mise en service | D17: Aération et ventilation: Installation à pollution spécifique avec système de recyclage Vérification à la mise en service établissement d''une notice d''instruction | E17: Des mesures, contrôles et examen doivent être effectué au plus tard un mois après la mise en service. | F17: CT. art. R. 4212-7 CT. art. R. 4212-3 CT. art. R. 4222-21 Arrêté du 08-10-1987, art 2 et 4. | H17: Ecart Détecté | M17: 1 | N17: 1 | O17: 1 | P17: 0 | Q17: =Y13 -> 1285 | R17: =Z13 -> 1739 | S17: 1 | T17: 5 | V17: Propriétaire | Y17: =VLOOKUP(A21,Feuil1!A:B,2,FALSE) -> 1285 | Z17: =VLOOKUP(A21,Feuil1!A:C,3,FALSE) -> 1741 | AA17: =CONCATENATE("insert into AOCR_ref_arbo (libelle,reglementation,typologie,pere,commentaires,personne_habilitee,type_cont,pere_superieur,criticite) values ('",Tableau6[[#This Row],[Obligation]],"','",Tableau6[[#This Row],[Référence]],"',1,",Tableau6[[#This Row],[ID Domaine2]],",'",Tableau6[[#This Row],[Libellé détaillé]],"','",Tableau6[[#This Row],[Possible réalisateur]],"',3,",Tableau6[[#This Row],[ID Domaine]],",",Tableau6[[#This Row],[Urgence]],")") -> insert into AOCR_ref_arbo (libelle,reglementation,typologie,pere,commentaires,personne_habilitee,type_cont,pere_superieur,criticite) values ('Aération et ventilation: Installation à pollution spécifique avec système de recyclage Vérification à la mise en service établissement d''une notice d''instruction','CT. art. R. 4212-7 CT. art. R. 4212-3 CT. art. R. 4222-21 Arrêté du 08-10-1987, art 2 et 4. ',1,1739,'Des mesures, contrôles et examen doivent être effectué au plus tard un mois après la mise en service.','',3,1285,5) | AB17: =CONCATENATE("update aocr_ref_arbo set libelle = '",Tableau6[[#This Row],[Obligation]],"', reglementation = '",Tableau6[[#This Row],[Référence]],"', commentaires = '",Tableau6[[#This Row],[Libellé détaillé]],"', personne_habilitee = '",Tableau6[[#This Row],[Possible réalisateur]],"', criticite = ",Tableau6[[#This Row],[Urgence]]," where id = ",Tableau6[[#This Row],[id]]) -> update aocr_ref_arbo set libelle = 'Aération et ventilation: Installation à pollution spécifique avec système de recyclage Vérification à la mise en service établissement d''une notice d''instruction', reglementation = 'CT. art. R. 4212-7 CT. art. R. 4212-3 CT. art. R. 4222-21 Arrêté du 08-10-1987, art 2 et 4. ', commentaires = 'Des mesures, contrôles et examen doivent être effectué au plus tard un mois après la mise en service.', personne_habilitee = '', criticite = 5 where id = 3702 | AC17: =IF(Tableau6[[#This Row],[Référence]]<>"",CONCATENATE("update aocr_ref_arbo set reglementation = '",Tableau6[[#This Row],[Référence]],"' where id = ",Tableau6[[#This Row],[id]]),"") -> update aocr_ref_arbo set reglementation = 'CT. art. R. 4212-7 CT. art. R. 4212-3 CT. art. R. 4222-21 Arrêté du 08-10-1987, art 2 et 4. ' where id = 3702
A18: 2232 | B18: Aération et ventilation | C18: Vérification Périodique 1 an | D18: Installation à pollution spécifique et non spécifique Vérification Périodique Annuelle : rapport de vérification et de maintenance | E18: Une maintenance périodique des installations à pollution non spécifique doit être effectué tous les ans. Au minimum une fois par an, les opérations suivantes doivent être effectuées : - contrôle du débit global minimal d''air neuf de l''installation ; - examen de l''état des éléments de l''installation (système d''introduction et d''extraction, gaines, ventilateurs) et plus particulièrement de la présence et de la conformité des filtres de rechange par rapport à la fourniture initiale (caractéristique, classe d''efficacité), de leurs dimensions, de leur perte de charge ; - examen de l''état des systèmes de traitement de l''air (humidificateur, batterie d''échangeurs) ; - lorsque le dossier de valeurs de référence est constitué, contrôle des pressions statiques ou des vitesses d''air aux points caractéristiques de l''installation. | F18: Article 3 Arrêté du 8 octobre 1987 CDT Art R4222-21 CDT Art R4222-22 | H18: Ecart Détecté | M18: 1 | N18: 1 | O18: 1 | P18: 0 | Q18: =Y14 -> 1285 | R18: =Z14 -> 1740 | S18: 1 | T18: 4 | V18: Locataire / Utilisateur | Y18: =VLOOKUP(A22,Feuil1!A:B,2,FALSE) -> 2 | Z18: =VLOOKUP(A22,Feuil1!A:C,3,FALSE) -> 1098 | AA18: =CONCATENATE("insert into AOCR_ref_arbo (libelle,reglementation,typologie,pere,commentaires,personne_habilitee,type_cont,pere_superieur,criticite) values ('",Tableau6[[#This Row],[Obligation]],"','",Tableau6[[#This Row],[Référence]],"',1,",Tableau6[[#This Row],[ID Domaine2]],",'",Tableau6[[#This Row],[Libellé détaillé]],"','",Tableau6[[#This Row],[Possible réalisateur]],"',3,",Tableau6[[#This Row],[ID Domaine]],",",Tableau6[[#This Row],[Urgence]],")") -> insert into AOCR_ref_arbo (libelle,reglementation,typologie,pere,commentaires,personne_habilitee,type_cont,pere_superieur,criticite) values ('Installation à pollution spécifique et non spécifique Vérification Périodique Annuelle : rapport de vérification et de maintenance','Article 3 Arrêté du 8 octobre 1987 CDT Art R4222-21 CDT Art R4222-22',1,1740,'Une maintenance périodique des installations à pollution non spécifique doit être effectué tous les ans. Au minimum une fois par an, les opérations suivantes doivent être effectuées : - contrôle du débit global minimal d''air neuf de l''installation ; - examen de l''état des éléments de l''installation (système d''introduction et d''extraction, gaines, ventilateurs) et plus particulièrement de la présence et de la conformité des filtres de rechange par rapport à la fourniture initiale (caractéristique, classe d''efficacité), de leurs dimensions, de leur perte de charge ; - examen de l''état des systèmes de traitement de l''air (humidificateur, batterie d''échangeurs) ; - lorsque le dossier de valeurs de référence est constitué, contrôle des pressions statiques ou des vitesses d''air aux points caractéristiques de l''installation.','',3,1285,4) | AB18: =CONCATENATE("update aocr_ref_arbo set libelle = '",Tableau6[[#This Row],[Obligation]],"', reglementation = '",Tableau6[[#This Row],[Référence]],"', commentaires = '",Tableau6[[#This Row],[Libellé détaillé]],"', personne_habilitee = '",Tableau6[[#This Row],[Possible réalisateur]],"', criticite = ",Tableau6[[#This Row],[Urgence]]," where id = ",Tableau6[[#This Row],[id]]) -> update aocr_ref_arbo set libelle = 'Installation à pollution spécifique et non spécifique Vérification Périodique Annuelle : rapport de vérification et de maintenance', reglementation = 'Article 3 Arrêté du 8 octobre 1987 CDT Art R4222-21 CDT Art R4222-22', commentaires = 'Une maintenance périodique des installations à pollution non spécifique doit être effectué tous les ans. Au minimum une fois par an, les opérations suivantes doivent être effectuées : - contrôle du débit global minimal d''air neuf de l''installation ; - examen de l''état des éléments de l''installation (système d''introduction et d''extraction, gaines, ventilateurs) et plus particulièrement de la présence et de la conformité des filtres de rechange par rapport à la fourniture initiale (caractéristique, classe d''efficacité), de leurs dimensions, de leur perte de charge ; - examen de l''état des systèmes de traitement de l''air (humidificateur, batterie d''échangeurs) ; - lorsque le dossier de valeurs de référence est constitué, contrôle des pressions statiques ou des vitesses d''air aux points caractéristiques de l''installation.', personne_habilitee = '', criticite = 4 where id = 2232 | AC18: =IF(Tableau6[[#This Row],[Référence]]<>"",CONCATENATE("update aocr_ref_arbo set reglementation = '",Tableau6[[#This Row],[Référence]],"' where id = ",Tableau6[[#This Row],[id]]),"") -> update aocr_ref_arbo set reglementation = 'Article 3 Arrêté du 8 octobre 1987 CDT Art R4222-21 CDT Art R4222-22' where id = 2232
A19: 3778 | B19: Aération et ventilation | C19: Vérification Périodique 1 an | D19: VMC-Gaz : Vérification Périodique 1 an | E19: Tous les ans au moins Le nettoyage des pales de ventilateur ; Le remplacement des courroies de transmission lorsqu'elles existent ; La vérification des paliers et des connexions électriques, des caractéristiques de fonctionnement du ventilateur (vitesse ou débit-pression, etc.) et du fonctionnement des alarmes éventuelles ; La vérification de la vacuité des conduits aérauliques, conduits collecteurs, conduits de liaison entre bouches d'extraction et conduits collecteurs, et du bon état des manchettes souples, des dispositifs de pied de conduits, des trappes de visite, des purges et siphons éventuels ; La vérification de l'état et du fonctionnement des bouches d'entrée d'air et d'extraction ainsi que leur entretien ou leur échange standard éventuel ; La vérification de la conformité à l'installation d'origine : absence de hottes ou armoires sèche-linge motorisées raccordées à la ventilation mécanique contrôlée - gaz, etc.. Le bon fonctionnement du système de détection de défaut du dispositif de sécurité collective ; " | F19: A. du 25-04-1985(1), art. 1 et 2. | H19: Ecart Détecté | P19: 0 | Q19: =Y15 -> 1285 | R19: =Z15 -> 1740 | T19: 4 | V19: Propriétaire | Y19: =VLOOKUP(A23,Feuil1!A:B,2,FALSE) -> 2 | Z19: =VLOOKUP(A23,Feuil1!A:C,3,FALSE) -> 1901 | AA19: =CONCATENATE("insert into AOCR_ref_arbo (libelle,reglementation,typologie,pere,commentaires,personne_habilitee,type_cont,pere_superieur,criticite) values ('",Tableau6[[#This Row],[Obligation]],"','",Tableau6[[#This Row],[Référence]],"',1,",Tableau6[[#This Row],[ID Domaine2]],",'",Tableau6[[#This Row],[Libellé détaillé]],"','",Tableau6[[#This Row],[Possible réalisateur]],"',3,",Tableau6[[#This Row],[ID Domaine]],",",Tableau6[[#This Row],[Urgence]],")") -> insert into AOCR_ref_arbo (libelle,reglementation,typologie,pere,commentaires,personne_habilitee,type_cont,pere_superieur,criticite) values ('VMC-Gaz : Vérification Périodique 1 an','A. du 25-04-1985(1), art. 1 et 2.',1,1740,'Tous les ans au moins Le nettoyage des pales de ventilateur ; Le remplacement des courroies de transmission lorsqu'elles existent ; La vérification des paliers et des connexions électriques, des caractéristiques de fonctionnement du ventilateur (vitesse ou débit-pression, etc.) et du fonctionnement des alarmes éventuelles ; La vérification de la vacuité des conduits aérauliques, conduits collecteurs, conduits de liaison entre bouches d'extraction et conduits collecteurs, et du bon état des manchettes souples, des dispositifs de pied de conduits, des trappes de visite, des purges et siphons éventuels ; La vérification de l'état et du fonctionnement des bouches d'entrée d'air et d'extraction ainsi que leur entretien ou leur échange standard éventuel ; La vérification de la conformité à l'installation d'origine : absence de hottes ou armoires sèche-linge motorisées raccordées à la ventilation mécanique contrôlée - gaz, etc.. Le bon fonctionnement du système de détection de défaut du dispositif de sécurité collective ; "','',3,1285,4) | AB19: =CONCATENATE("update aocr_ref_arbo set libelle = '",Tableau6[[#This Row],[Obligation]],"', reglementation = '",Tableau6[[#This Row],[Référence]],"', commentaires = '",Tableau6[[#This Row],[Libellé détaillé]],"', personne_habilitee = '",Tableau6[[#This Row],[Possible réalisateur]],"', criticite = ",Tableau6[[#This Row],[Urgence]]," where id = ",Tableau6[[#This Row],[id]]) -> update aocr_ref_arbo set libelle = 'VMC-Gaz : Vérification Périodique 1 an', reglementation = 'A. du 25-04-1985(1), art. 1 et 2.', commentaires = 'Tous les ans au moins Le nettoyage des pales de ventilateur ; Le remplacement des courroies de transmission lorsqu'elles existent ; La vérification des paliers et des connexions électriques, des caractéristiques de fonctionnement du ventilateur (vitesse ou débit-pression, etc.) et du fonctionnement des alarmes éventuelles ; La vérification de la vacuité des conduits aérauliques, conduits collecteurs, conduits de liaison entre bouches d'extraction et conduits collecteurs, et du bon état des manchettes souples, des dispositifs de pied de conduits, des trappes de visite, des purges et siphons éventuels ; La vérification de l'état et du fonctionnement des bouches d'entrée d'air et d'extraction ainsi que leur entretien ou leur échange standard éventuel ; La vérification de la conformité à l'installation d'origine : absence de hottes ou armoires sèche-linge motorisées raccordées à la ventilation mécanique contrôlée - gaz, etc.. Le bon fonctionnement du système de détection de défaut du dispositif de sécurité collective ; "', personne_habilitee = '', criticite = 4 where id = 3778 | AC19: =IF(Tableau6[[#This Row],[Référence]]<>"",CONCATENATE("update aocr_ref_arbo set reglementation = '",Tableau6[[#This Row],[Référence]],"' where id = ",Tableau6[[#This Row],[id]]),"") -> update aocr_ref_arbo set reglementation = 'A. du 25-04-1985(1), art. 1 et 2.' where id = 3778
